Workbook

Sheet ARN samples
A1: Muesta | B1: ID | C1: Tagma | D1: Tratamiento | E1: Sexo | F1: Concentración(ng/ul) | G1: A260/280 | H1: A260/230
A2: 1 | B2: 01.H | C2: Cabeza | D2: Cold | E2: Female | F2: 273.7 | G2: 2.04 | H2: 1.3
A3: 2 | B3: 01.T | C3: Torax | D3: Cold | E3: Female | F3: 338.7 | G3: 2.14 | H3: 2.28
A4: 3 | B4: 01.A | C4: Abdomen | D4: Cold | E4: Female | F4: 256.9 | G4: 2.04 | H4: 1.62
A5: 4 | B5: 02.H | C5: Cabeza | D5: Cold | E5: Female | F5: 323.1 | G5: 2.03 | H5: 1.26
A6: 5 | B6: 02.T | C6: Torax | D6: Cold | E6: Female | F6: 506.5 | G6: 2.21 | H6: 2.27
A7: 6 | B7: 02.A | C7: Abdomen | D7: Cold | E7: Female | F7: 209 | G7: 1.22 | H7: 0.95
A8: 7 | B8: 03.H | C8: Cabeza | D8: Cold | E8: Female | F8: 534.9 | G8: 2.01 | H8: 1.16
A9: 8 | B9: 03.T | C9: Torax | D9: Cold | E9: Female | F9: 101.1 | G9: 2.12 | H9: 2.33
A10: 9 | B10: 03.A | C10: Abdomen | D10: Cold | E10: Female | F10: 167.8 | G10: 1.78 | H10: 1.32
A11: 10 | B11: 04.H | C11: Cabeza | D11: Control | E11: Female | F11: 200.5 | G11: 2.02 | H11: 0.98
A12: 11 | B12: 04.T | C12: Torax | D12: Control | E12: Female | F12: 161.9 | G12: 2.17 | H12: 1.52
A13: 12 | B13: 04.A | C13: Abdomen | D13: Control | E13: Female | F13: 313 | G13: 1.99 | H13: 1.64
... A17: 16 | B17: 06.H | C17: Cabeza | D17: Control | E17: Female | F17: 81.7 | G17: 1.95 | H17: 0.77
A18: 17 | B18: 06.T | C18: Torax | D18: Control | E18: Female | F18: 331 | G18: =(80*20)/(F18) -> 4.8338369 | H18: =20-G18 -> 15.166163
A19: 18 | B19: 06.A | C19: Abdomen | D19: Control | E19: Female | F19: 146.6 | G19: 1.92 | H19: 1.37
A20: 19 | B20: 17.H | C20: Cabeza | D20: Heat | E20: Female | F20: 437.4 | G20: 2.13 | H20: 1.39
A21: 20 | B21: 17.T | C21: Torax | D21: Heat | E21: Female | F21: 240.7 | G21: 2.23 | H21: 1.56
A22: 21 | B22: 17.A | C22: Abdomen | D22: Heat | E22: Female | F22: 235.2 | G22: 2.12 | H22: 1.71
A23: 22 | B23: 18.H | C23: Cabeza | D23: Heat | E23: Female | F23: 263.2 | G23: 2.09 | H23: 1.22
A24: 23 | B24: 18.T | C24: Torax | D24: Heat | E24: Female | F24: 254.8 | G24: 2.21 | H24: 1.38
A25: 24 | B25: 18.A | C25: Abdomen | D25: Heat | E25: Female | F25: 506.1 | G25: 2.05 | H25: 1.72
A26: 25 | B26: 19.H | C26: Cabeza | D26: Heat | E26: Female | F26: 104 | G26: 2.2 | H26: 0.69
A27: 26 | B27: 19.T | C27: Torax | D27: Heat | E27: Female | F27: 67.6 | G27: 2.18 | H27: 0.38
A28: 27 | B28: 19.A | C28: Abdomen | D28: Heat | E28: Female | F28: 371.9 | G28: 2.19 | H28: 1.19
A29: 28 | B29: 08.H | C29: Cabeza | D29: Cold | E29: Male | F29: 252.8 | G29: 1.92 | H29: 0.8
A30: 29 | B30: 08.T | C30: Torax | D30: Cold | E30: Male | F30: 190.6 | G30: 2.19 | H30: 1.48
... A55: 54 | B55: 25.A | C55: Abdomen | D55: Heat | E55: Male | F55: 678.9 | G55: 2.16 | H55: 1.73

Sheet Treatments data
A1: Treatment | B1: Tagma | C1: Actin1 | D1: Actin2 | E1: Arginine | F1: Annexin | G1: Eefa1 | H1: pAbp | I1: RPL3 | J1: GAPDH | K1: UCCR
A2: Control | B2: Head | C2: 22.100818 | D2: 24.667399 | E2: 25.668875 | F2: 24.719096 | G2: 23.769943 | H2: 27.1 | I2: 23.17 | J2: 25.46 | K2: 25.56
A3: Control | B3: Head | C3: 18.636753 | D3: 20.163566 | E3: 20.355335 | F3: 22.407964 | G3: 19.101691 | H3: 21.81 | I3: 20.65 | J3: 22.62 | K3: 24
A4: Control | B4: Head | C4: 22.846 | D4: 22.853911 | E4: 22.611362 | F4: 26.393393 | G4: 22.609641 | H4: 26.15 | I4: 25.43 | J4: 29.39 | K4: 24.98
A5: Control | B5: Head | C5: 28.266931 | D5: 29.771993 | E5: 30.235778 | F5: 26.554807 | G5: 28.924044 | H5: 32.32 | I5: 25.18 | J5: 24.61 | K5: 30.58
A6: Control | B6: Head | C6: 23.982912 | D6: 23.174026 | E6: 23.080353 | F6: 28.100548 | G6: 24.366075 | H6: 25.75 | I6: 26.33 | J6: 23.32 | K6: 26.92
A7: Control | B7: Head | C7: 26.548404 | D7: 28.907664 | E7: 28.346161 | F7: 25.455894 | G7: 25.946921 | H7: 31.09 | I7: 23.52 | J7: 23.34 | K7: 29.07
A8: Control | B8: Abdomen | C8: 24.680436 | D8: 25.435337 | E8: 26.76873 | F8: 29.566304 | G8: 23.516823 | H8: 28.65 | I8: 20.7 | J8: 27.27 | K8: 24.46
A9: Control | B9: Abdomen | C9: 24.11896 | D9: 25.594712 | E9: 25.856609 | F9: 29.448887 | G9: 24.879456 | H9: 28.11 | I9: 27.38 | J9: 26.8 | K9: 30.44
A10: Control | B10: Abdomen | C10: 23.963906 | D10: 24.639922 | E10: 24.896555 | F10: 30.309502 | G10: 24.632799 | H10: 28.63 | I10: 27.7 | J10: 30.63 | K10: 28.17
A11: Control | B11: Abdomen | C11: 29.438856 | D11: 31.099652 | E11: 31.78965 | F11: 35.05161 | G11: 32.205246 | H11: 33.75 | I11: 31.77 | J11: 37.56 | K11: 33.11
A12: Control | B12: Abdomen | C12: 27.790877 | D12: 29.024148 | E12: 31.07188 | F12: 31.20263 | G12: 28.095244 | H12: 32.39 | I12: 27.88 | J12: 24.7 | K12: 29.95
A13: Control | B13: Abdomen | C13: 25.892402 | D13: 25.953586 | E13: 26.353802 | F13: 29.364456 | G13: 25.808002 | H13: 30.41 | I13: 26.12 | J13: 33.19 | K13: 30.1
... A19: Control | B19: Thorax | C19: 18.486354 | D19: 18.28024 | E19: 18.726071 | F19: 21.192468 | G19: 20.6402 | H19: 23.5 | I19: 20.2 | J19: 24.24 | K19: 21.51
A22: Treatment | B22: Sex | C22: Actin1 | D22: Actin2 | E22: Arginine | F22: Annexin | G22: Eefa1 | H22: pAbp | I22: RPL3 | J22: GAPDH | K22: Ubiquinol
A23: Control | B23: Hembra | C23: 20.89628 | D23: 22.08079 | E23: 23.019899 | F23: 25.32368 | G23: 21.98347 | H23: 25.353333 | I23: 23.703333 | J23: 26.51 | K23: 24.796667
A24: Control | B24: Hembra | C24: 19.260302 | D24: 20.248119 | E24: 20.739984 | F24: 24.29938 | G24: 20.735424 | H24: 23.236667 | I24: 22.563333 | J24: 23.343333 | K24: 24.226667
A25: Control | B25: Hembra | C25: 20.787977 | D25: 21.027891 | E25: 21.35481 | F25: 25.875047 | G25: 21.898674 | H25: 25.03 | I25: 24.533333 | J25: 26.903333 | K25: 24.17
A26: Control | B26: Macho | C26: 24.853807 | D26: 26.223866 | E26: 27.011995 | F26: 28.077857 | G26: 27.631989 | H26: 30.1 | I26: 26.023333 | J26: 27.616667 | K26: 28.37
A27: Control | B27: Macho | C27: 22.823921 | D27: 23.730358 | E27: 24.737925 | F27: 27.442905 | G27: 24.885836 | H27: 27.496667 | I27: 25.403333 | J27: 24.136667 | K27: 25.836667
A28: Control | B28: Macho | C28: 23.642387 | D28: 24.380497 | E28: 24.475345 | F28: 25.337606 | G28: 24.131708 | H28: 28.333333 | I28: 23.28 | J28: 26.923333 | K28: 26.893333
A31: Treatment | B31: Tagma | C31: Actin1 | D31: Actin2 | E31: Arginine | F31: Annexin | G31: Eefa1 | H31: pAbp | I31: RPL3 | J31: GAPDH | K31: Ubiquinol
A32: Cold | B32: Head | C32: 19.841928 | D32: 22.248229 | E32: 22.294819 | F32: 25.029229 | G32: 21.953804 | H32: 24.14 | I32: 23.32 | J32: 20.4 | K32: 25.02
A33: Cold | B33: Thorax | C33: 17.969883 | D33: 17.074513 | E33: 18.143235 | F33: 22.42931 | G33: 20.183704 | H33: 21.57 | I33: 21.24 | J33: 22.44 | K33: 21.54
A34: Cold | B34: Abdomen | C34: 25.863309 | D34: 23.528552 | E34: 26.50389 | F34: 29.823382 | G34: 25.119233 | H34: 28.42 | I34: 27.02 | J34: 33.66 | K34: 28.9
A35: Cold | B35: Head | C35: 19.79078 | D35: 20.35359 | E35: 20.564129 | F35: 22.456866 | G35: 19.366711 | H35: 21.96 | I35: 21.3 | J35: 24.68 | K35: 23.17
A36: Cold | B36: Thorax | C36: 15.842229 | D36: 16.303785 | E36: 17.061207 | F36: 20.753771 | G36: 19.131868 | H36: 20.23 | I36: 20.05 | J36: 21.48 | K36: 19.73
A37: Cold | B37: Abdomen | C37: 25.33003 | D37: 26.663482 | E37: 27.487917 | F37: 31.029522 | G37: 26.158998 | H37: 28.57 | I37: 28.22 | J37: 32.83 | K37: 30.25
A38: Cold | B38: Head | C38: 22.329423 | D38: 25.781675 | E38: 26.987208 | F38: 24.536956 | G38: 24.129632 | H38: 27.56 | I38: 21.29 | J38: 26.18 | K38: 25.29
A39: Cold | B39: Thorax | C39: 15.627483 | D39: 17.315194 | E39: 18.647953 | F39: 22.012114 | G39: 19.960732 | H39: 21.6 | I39: 21.14 | J39: 16.32 | K39: 21.24
A40: Cold | B40: Abdomen | C40: 25.108899 | D40: 26.06203 | E40: 27.472841 | F40: 27.706764 | G40: 23.4665 | H40: 27.05 | I40: 25.05 | J40: 22.54 | K40: 28.26
A41: Cold | B41: Head | C41: 20.573944 | D41: 20.334045 | E41: 19.54172 | F41: 22.237882 | G41: 18.224447 | H41: 20.38 | I41: 21.03 | J41: 23.65 | K41: 22.84
A42: Cold | B42: Thorax | C42: 15.122657 | D42: 14.816428 | E42: 16.325432 | F42: 20.228166 | G42: 18.066143 | H42: 19.98 | I42: 19.57 | J42: 20.72 | K42: 18.9
A43: Cold | B43: Abdomen | C43: 21.074509 | D43: 21.533908 | E43: 22.837213 | F43: 26.272279 | G43: 20.34959 | H43: 24.52 | I43: 23.66 | J43: 26.77 | K43: 25.68
... A85: Heat | B85: Abdomen | C85: 20.240866 | D85: 20.82306 | E85: 22.230049 | F85: 26.467432 | G85: 21.999948 | H85: 26.71 | I85: 24.18 | J85: 23.17 | K85: 25.59
A88: Treatment | B88: Sex | C88: Tagma | D88: Actin1 | E88: Actin2 | F88: Arginine | G88: Annexin | H88: Eefa1 | I88: RPS3A | J88: RPL3 | K88: GAPDH | L88: Ubiquinol
A89: Cold | B89: Hembra | C89: Head | D89: 19.841928 | E89: 22.248229 | F89: 22.294819 | G89: 25.029229 | H89: 21.953804 | I89: 23.22 | J89: 23.32 | K89: 20.4 | L89: 25.02
A90: Cold | B90: Hembra | C90: Head | D90: 19.79078 | E90: 20.35359 | F90: 20.564129 | G90: 22.456866 | H90: 19.366711 | I90: 21.25 | J90: 21.3 | K90: 24.68 | L90: 23.17
A91: Cold | B91: Hembra | C91: Head | D91: 22.329423 | E91: 25.781675 | F91: 26.987208 | G91: 24.536956 | H91: 24.129632 | I91: 22.13 | J91: 21.29 | K91: 26.18 | L91: 25.29
A92: Cold | B92: Hembra | C92: Thorax | D92: 17.969883 | E92: 17.074513 | F92: 18.143235 | G92: 22.42931 | H92: 20.183704 | I92: 21.35 | J92: 21.24 | K92: 22.44 | L92: 21.54
...

Sheet qPCR raw data
A1: Primers | B1: Eq | C1: b | D1: m | E1: Amplicón | F1: Amp. Size | H1: bases | I1: Formulas: | J1: Cuantificacion Absoluta
A2: Actin1 | B2: X = (Y - 21,786)/(-3,369) | C2: 21.786 | D2: -3.369 | E2: 131 | F2: Avogadro | G2: =6.022*10^23 -> 6.022e+23 | H2: Constant
A3: Actin2 | B3: X = (Y - 24,365)/(-3,200) | C3: 24.365 | D3: -3.2 | E3: 125 | F3: BP weight | G3: 660 | H3: Da
A4: eEFA1 | B4: X = (Y - 25,688)/(-3,575) | C4: 25.688 | D4: -3.575 | E4: 120 | F4: DNA con | G4: =1000000000 -> 1000000000 | H4: g/uL
A5: Arginine | B5: X = (Y - 24,976)/(-3,512) | C5: 24.976 | D5: 3.512 | E5: 131
A6: Annexine | B6: X = (Y - 27,515)/(-3,358) | C6: 27.515 | D6: -3.358 | E6: 125
A7: pAbp | B7: X = (Y - 27.662)/(-3.439) | C7: 27.662 | D7: =-3.439 -> -3.439 | E7: 108
A8: S3A | B8: X = (Y - 25.686)/(-3.2528) | C8: 25.686 | D8: -3.2528 | E8: 132
A9: L3 | B9: X = (Y - 26.72)/(-3.387) | C9: 26.679 | D9: =-3.176 -> -3.176 | E9: 111
A10: GAPDH | B10: X = (Y - 26.72)/(-3.387) | C10: 28.867 | D10: -3.563 | E10: 122
A11: Ubiquinol | B11: X = (Y - 26.72)/(-3.387) | C11: 25.531 | D11: -3.244 | E11: 96
AG12: Absolute expression
A13: Treatment | B13: Sex | C13: Tissue | D13: ACTINA1_1 | E13: Actin1_2 | F13: AV_Actin1 | G13: Actin2_1 | H13: Actin2_2 | I13: AV_Actin2 | J13: Arginine1 | K13: Arginine2 | L13: Av_arginine | M13: Annexin_1 | N13: Annexin_2 | O13: Av_Annexin | P13: Eefa1_1 | Q13: eEFA1_2 | R13: Av_Eefa1 | S13: pAbp | T13: RPS3A | U13: RPL3 | V13: GAPDH | W13: Ubiquinol | X13: Av_HSP90 | Y13: Aq_Actin1 | Z13: Aq_Actin2 | AA13: Aq_Arginine | AB13: Aq_Annexin | AC13: Aq_eEFA1 | AD13: Aq pAbp | AE13: Aq S3A | AF13: Aq L3 | AG13: Aq GAPDH | AH13: Aq Ubiquinol | AI13: NC_Actin1 | AJ13: NC_Actin2 | AK13: NC_Arginine | AL13: NC_Annexin | AM13: NC_Eefa1 | AN13: NC_pAbp | AO13: NC_S3A | AP13: NC_L3 | AQ13: NC_GAPDH | AR13: NC_Ubiquinol
A14: Cold | B14: Hembra | C14: Head | D14: 20.24 | E14: 19.45 | F14: 19.84 | G14: 21.43 | H14: 23.07 | I14: 22.25 | J14: 22.5 | K14: 22.09 | L14: 22.29 | M14: 24.94 | N14: 25.11 | O14: 25.03 | P14: 22.16 | Q14: 21.75 | R14: 21.95 | S14: 24.14 | T14: 23.22 | U14: 23.32 | V14: 20.4 | W14: 25.02 | X14: 28.537491 | Y14: =10^((#REF!-C$2)/D$2) -> #REF! | Z14: =10^((#REF!-C$3)/D$3) -> #REF! | AA14: =10^((#REF!-C$5)/D$5) -> #REF! | AB14: =10^((#REF!-C$6)/D$6) -> #REF! | AC14: =10^((#REF!-C$4)/D$4) -> #REF! | AD14: =10^((S14-C$7)/D$7) -> 10.571459 | AE14: =10^((T14-C$8)/D$8) -> 5.7294916 | AF14: =10^((U14-C$9)/D$9) -> 11.418778 | AG14: =10^((V14-C$10)/D$10) -> 237.88564 | AH14: =10^((W14-C$11)/D$11) -> 1.4372145 | AI14: =($G$2*Y14/G$4)/($E$2*G$3) -> #REF! | AJ14: =($G$2*Z14/$G$4)/($E$3*G$3) -> #REF! | AK14: =($G$2*AA14/$G$4)/($E$5*G$3) -> #REF! | AL14: =($G$2*AB14/$G$4)/($E$6*G$3) -> #REF! | AM14: =($G$2*AC14/$G$4)/($E$4*G$3) -> #REF! | AN14: =($G$2*AD14/$G$4)/($E$7*G$3) -> 8.9311623e+10 | AO14: =($G$2*AE14/$G$4)/($E$8*G$3) -> 3.9603992e+10 | AP14: =($G$2*AF14/$G$4)/($E$9*G$3) -> 9.3862795e+10 | AQ14: =($G$2*AG14/$G$4)/($E$10*G$3) -> 1.7791199e+12 | AR14: =($G$2*AH14/$G$4)/($E$11*G$3) -> 1.3659889e+10
A15: Cold | B15: Hembra | C15: Thorax | D15: 18.2 | E15: 17.74 | F15: 17.97 | G15: 17.01 | H15: 17.13 | I15: 17.07 | J15: 18.26 | K15: 18.03 | L15: 18.14 | M15: 22.54 | N15: 22.31 | O15: 22.43 | P15: 20.3 | Q15: 20.07 | R15: 20.18 | S15: 21.57 | T15: 21.35 | U15: 21.24 | V15: 22.44 | W15: 21.54 | X15: 24.483693 | Y15: =10^((#REF!-C$2)/D$2) -> #REF! | Z15: =10^((#REF!-C$3)/D$3) -> #REF! | AA15: =10^((#REF!-C$5)/D$5) -> #REF! | AB15: =10^((#REF!-C$6)/D$6) -> #REF! | AC15: =10^((#REF!-C$4)/D$4) -> #REF! | AD15: =10^((S15-C$7)/D$7) -> 59.08064 | AE15: =10^((T15-D$8)/E$8) -> 1.5359775 | AF15: =10^((U15-C$9)/D$9) -> 51.585956 | AG15: =10^((V15-C$10)/D$10) -> 63.652726 | AH15: =10^((W15-C$11)/D$11) -> 16.993047 | AI15: =($G$2*Y15/G$4)/($E$2*G$3) -> #REF! | AJ15: =($G$2*Z15/$G$4)/($E$3*G$3) -> #REF! | AK15: =($G$2*AA15/$G$4)/($E$5*G$3) -> #REF! | AL15: =($G$2*AB15/$G$4)/($E$6*G$3) -> #REF! | AM15: =($G$2*AC15/$G$4)/($E$4*G$3) -> #REF! | AN15: =($G$2*AD15/$G$4)/($E$7*G$3) -> 4.9913526e+11 | AO15: =($G$2*AE15/$G$4)/($E$8*G$3) -> 1.0617145e+10 | AP15: =($G$2*AF15/$G$4)/($E$9*G$3) -> 4.2403853e+11 | AQ15: =($G$2*AG15/$G$4)/($E$10*G$3) -> 4.7605156e+11 | AR15: =($G$2*AH15/$G$4)/($E$11*G$3) -> 1.6150905e+11
A16: Cold | B16: Hembra | C16: Abdomen | D16: 25.69 | E16: 26.03 | F16: 25.86 | G16: 22.98 | H16: 24.07 | I16: 23.53 | J16: 26.56 | K16: 26.44 | L16: 26.5 | M16: 30.1 | N16: 29.55 | O16: 29.82 | P16: 25.36 | Q16: 24.88 | R16: 25.12 | S16: 28.42 | T16: 27.55 | U16: 27.02 | V16: 33.66 | W16: 28.9 | X16: 24.481112 | Y16: =10^((#REF!-C$2)/D$2) -> #REF! | Z16: =10^((#REF!-C$3)/D$3) -> #REF! | AA16: =10^((#REF!-C$5)/D$5) -> #REF! | AB16: =10^((#REF!-C$6)/D$6) -> #REF! | AC16: =10^((#REF!-C$4)/D$4) -> #REF! | AD16: =10^((S16-C$7)/D$7) -> 0.60198697 | AE16: =10^((T16-D$8)/E$8) -> 1.7114119 | AF16: =10^((U16-C$9)/D$9) -> 0.78096621 | AG16: =10^((V16-C$10)/D$10) -> 0.045163261 | AH16: =10^((W16-C$11)/D$11) -> 0.091509741 | AI16: =($G$2*Y16/G$4)/($E$2*G$3) -> #REF! | AJ16: =($G$2*Z16/$G$4)/($E$3*G$3) -> #REF! | AK16: =($G$2*AA16/$G$4)/($E$5*G$3) -> #REF! | AL16: =($G$2*AB16/$G$4)/($E$6*G$3) -> #REF! | AM16: =($G$2*AC16/$G$4)/($E$4*G$3) -> #REF! | AN16: =($G$2*AD16/$G$4)/($E$7*G$3) -> 5.0858102e+09 | AO16: =($G$2*AE16/$G$4)/($E$8*G$3) -> 1.1829801e+10 | AP16: =($G$2*AF16/$G$4)/($E$9*G$3) -> 6.4195721e+09 | AQ16: =($G$2*AG16/$G$4)/($E$10*G$3) -> 3.3777094e+08 | AR16: =($G$2*AH16/$G$4)/($E$11*G$3) -> 8.6974693e+08
A17: Cold | B17: Hembra | C17: Head | D17: 19.69 | E17: 19.89 | F17: 19.79 | G17: 20.34 | H17: 20.37 | I17: 20.35 | J17: 20.47 | K17: 20.66 | L17: 20.56 | M17: 22.44 | N17: 22.47 | O17: 22.46 | P17: 19.54 | Q17: 19.19 | R17: 19.37 | S17: 21.96 | T17: 21.25 | U17: 21.3 | V17: 24.68 | W17: 23.17 | X17: 30.584744 | Y17: =10^((#REF!-C$2)/D$2) -> #REF! | Z17: =10^((#REF!-C$3)/D$3) -> #REF! | AA17: =10^((#REF!-C$5)/D$5) -> #REF! | AB17: =10^((#REF!-C$6)/D$6) -> #REF! | AC17: =10^((#REF!-C$4)/D$4) -> #REF! | AD17: =10^((S17-C$7)/D$7) -> 45.50301 | AE17: =10^((T17-D$8)/E$8) -> 1.5333005 | AF17: =10^((U17-C$9)/D$9) -> 49.390088 | AG17: =10^((V17-C$10)/D$10) -> 14.96695 | AH17: =10^((W17-C$11)/D$11) -> 5.3432461 | AI17: =($G$2*Y17/G$4)/($E$2*G$3) -> #REF! | AJ17: =($G$2*Z17/$G$4)/($E$3*G$3) -> #REF! | AK17: =($G$2*AA17/$G$4)/($E$5*G$3) -> #REF! | AL17: =($G$2*AB17/$G$4)/($E$6*G$3) -> #REF! | AM17: =($G$2*AC17/$G$4)/($E$4*G$3) -> #REF! | AN17: =($G$2*AD17/$G$4)/($E$7*G$3) -> 3.8442639e+11 | AO17: =($G$2*AE17/$G$4)/($E$8*G$3) -> 1.059864e+10 | AP17: =($G$2*AF17/$G$4)/($E$9*G$3) -> 4.0598841e+11 | AQ17: =($G$2*AG17/$G$4)/($E$10*G$3) -> 1.1193613e+11 | AR17: =($G$2*AH17/$G$4)/($E$11*G$3) -> 5.0784451e+10
A18: Cold | B18: Hembra | C18: Thorax | D18: 15.78 | E18: 15.9 | F18: 15.84 | G18: 16.39 | H18: 16.22 | I18: 16.3 | J18: 17.11 | K18: 17.01 | L18: 17.06 | M18: 20.91 | N18: 20.6 | O18: 20.75 | P18: 19.15 | Q18: 19.11 | R18: 19.13 | S18: 20.23 | T18: 21.3 | U18: 20.05 | V18: 21.48 | W18: 19.73 | X18: 26.912748 | Y18: =10^((#REF!-C$2)/D$2) -> #REF! | Z18: =10^((#REF!-C$3)/D$3) -> #REF! | AA18: =10^((#REF!-C$5)/D$5) -> #REF! | AB18: =10^((#REF!-C$6)/D$6) -> #REF! | AC18: =10^((#REF!-C$4)/D$4) -> #REF! | AD18: =10^((S18-C$7)/D$7) -> 144.90833 | AE18: =10^((T18-D$8)/E$8) -> 1.5346384 | AF18: =10^((U18-C$9)/D$9) -> 122.24092 | AG18: =10^((V18-C$10)/D$10) -> 118.37306 | AH18: =10^((W18-C$11)/D$11) -> 61.407924 | AI18: =($G$2*Y18/G$4)/($E$2*G$3) -> #REF! | AJ18: =($G$2*Z18/$G$4)/($E$3*G$3) -> #REF! | AK18: =($G$2*AA18/$G$4)/($E$5*G$3) -> #REF! | AL18: =($G$2*AB18/$G$4)/($E$6*G$3) -> #REF! | AM18: =($G$2*AC18/$G$4)/($E$4*G$3) -> #REF! | AN18: =($G$2*AD18/$G$4)/($E$7*G$3) -> 1.2242395e+12 | AO18: =($G$2*AE18/$G$4)/($E$8*G$3) -> 1.0607888e+10 | AP18: =($G$2*AF18/$G$4)/($E$9*G$3) -> 1.0048251e+12 | AQ18: =($G$2*AG18/$G$4)/($E$10*G$3) -> 8.8529877e+11 | AR18: =($G$2*AH18/$G$4)/($E$11*G$3) -> 5.8364665e+11
A19: Cold | B19: Hembra | C19: Abdomen | D19: 25.08 | E19: 25.58 | F19: 25.33 | G19: 26.66 | H19: 26.67 | I19: 26.66 | J19: 27.63 | K19: 27.34 | L19: 27.49 | M19: 31.02 | N19: 31.04 | O19: 31.03 | P19: 26.13 | Q19: 26.19 | R19: 26.16 | S19: 28.57 | T19: 29.87 | U19: 28.22 | V19: 32.83 | W19: 30.25 | X19: 23.413045 | Y19: =10^((#REF!-C$2)/D$2) -> #REF! | Z19: =10^((#REF!-C$3)/D$3) -> #REF! | AA19: =10^((#REF!-C$5)/D$5) -> #REF! | AB19: =10^((#REF!-C$6)/D$6) -> #REF! | AC19: =10^((#REF!-C$4)/D$4) -> #REF! | AD19: =10^((S19-C$7)/D$7) -> 0.54446474 | AE19: =10^((T19-D$8)/E$8) -> 1.7820927 | AF19: =10^((U19-C$9)/D$9) -> 0.32718885 | AG19: =10^((V19-C$10)/D$10) -> 0.077220935 | AH19: =10^((W19-C$11)/D$11) -> 0.035100591 | AI19: =($G$2*Y19/G$4)/($E$2*G$3) -> #REF! | AJ19: =($G$2*Z19/$G$4)/($E$3*G$3) -> #REF! | AK19: =($G$2*AA19/$G$4)/($E$5*G$3) -> #REF! | AL19: =($G$2*AB19/$G$4)/($E$6*G$3) -> #REF! | AM19: =($G$2*AC19/$G$4)/($E$4*G$3) -> #REF! | AN19: =($G$2*AD19/$G$4)/($E$7*G$3) -> 4.599841e+09 | AO19: =($G$2*AE19/$G$4)/($E$8*G$3) -> 1.2318368e+10 | AP19: =($G$2*AF19/$G$4)/($E$9*G$3) -> 2.6895048e+09 | AQ19: =($G$2*AG19/$G$4)/($E$10*G$3) -> 5.7752666e+08 | AR19: =($G$2*AH19/$G$4)/($E$11*G$3) -> 3.3361073e+08
A20: Cold | B20: Hembra | C20: Head | D20: 22.45 | E20: 22.21 | F20: 22.33 | G20: 25.79 | H20: 25.77 | I20: 25.78 | J20: 27.19 | K20: 26.78 | L20: 26.99 | M20: 24.9 | N20: 24.17 | O20: 24.54 | P20: 24.26 | Q20: 24 | R20: 24.13 | S20: 27.56 | T20: 22.13 | U20: 21.29 | V20: 26.18 | W20: 25.29 | X20: 33.792298 | Y20: =10^((#REF!-C$2)/D$2) -> #REF! | Z20: =10^((#REF!-C$3)/D$3) -> #REF! | AA20: =10^((#REF!-C$5)/D$5) -> #REF! | AB20: =10^((#REF!-C$6)/D$6) -> #REF! | AC20: =10^((#REF!-C$4)/D$4) -> #REF! | AD20: =10^((S20-C$7)/D$7) -> 1.0706802 | AE20: =10^((T20-D$8)/E$8) -> 1.5570191 | AF20: =10^((U20-C$9)/D$9) -> 49.749465 | AG20: =10^((V20-C$10)/D$10) -> 5.6772729 | AH20: =10^((W20-C$11)/D$11) -> 1.1865635 | AI20: =($G$2*Y20/G$4)/($E$2*G$3) -> #REF! | AJ20: =($G$2*Z20/$G$4)/($E$3*G$3) -> #REF! | AK20: =($G$2*AA20/$G$4)/($E$5*G$3) -> #REF! | AL20: =($G$2*AB20/$G$4)/($E$6*G$3) -> #REF! | AM20: =($G$2*AC20/$G$4)/($E$4*G$3) -> #REF! | AN20: =($G$2*AD20/$G$4)/($E$7*G$3) -> 9.0455056e+09 | AO20: =($G$2*AE20/$G$4)/($E$8*G$3) -> 1.0762591e+10 | AP20: =($G$2*AF20/$G$4)/($E$9*G$3) -> 4.089425e+11 | AQ20: =($G$2*AG20/$G$4)/($E$10*G$3) -> 4.2459684e+10 | AR20: =($G$2*AH20/$G$4)/($E$11*G$3) -> 1.1277597e+10
A21: Cold | B21: Hembra | C21: Thorax | D21: 15.46 | E21: 15.79 | F21: 15.63 | G21: 17.44 | H21: 17.19 | I21: 17.32 | J21: 18.7 | K21: 18.6 | L21: 18.65 | M21: 22 | N21: 22.03 | O21: 22.01 | P21: 20.03 | Q21: 19.9 | R21: 19.96 | S21: 21.6 | T21: 21.19 | U21: 21.14 | V21: 16.32 | W21: 21.24 | X21: 27.235091 | Y21: =10^((#REF!-C$2)/D$2) -> #REF! | Z21: =10^((#REF!-C$3)/D$3) -> #REF! | AA21: =10^((#REF!-C$5)/D$5) -> #REF! | AB21: =10^((#REF!-C$6)/D$6) -> #REF! | AC21: =10^((#REF!-C$4)/D$4) -> #REF! | AD21: =10^((S21-C$7)/D$7) -> 57.905754 | AE21: =10^((T21-D$8)/E$8) -> 1.5316965 | AF21: =10^((U21-C$9)/D$9) -> 55.464823 | AG21: =10^((V21-C$10)/D$10) -> 3322.5435 | AH21: =10^((W21-C$11)/D$11) -> 21.025663 | AI21: =($G$2*Y21/G$4)/($E$2*G$3) -> #REF! | AJ21: =($G$2*Z21/$G$4)/($E$3*G$3) -> #REF! | AK21: =($G$2*AA21/$G$4)/($E$5*G$3) -> #REF! | AL21: =($G$2*AB21/$G$4)/($E$6*G$3) -> #REF! | AM21: =($G$2*AC21/$G$4)/($E$4*G$3) -> #REF! | AN21: =($G$2*AD21/$G$4)/($E$7*G$3) -> 4.8920939e+11 | AO21: =($G$2*AE21/$G$4)/($E$8*G$3) -> 1.0587553e+10 | AP21: =($G$2*AF21/$G$4)/($E$9*G$3) -> 4.5592297e+11 | AQ21: =($G$2*AG21/$G$4)/($E$10*G$3) -> 2.4848928e+13 | AR21: =($G$2*AH21/$G$4)/($E$11*G$3) -> 1.9983671e+11
A22: Cold | B22: Hembra | C22: Abdomen | D22: 25.21 | E22: 25.01 | F22: 25.11 | G22: 26.08 | H22: 26.05 | I22: 26.06 | J22: 27.46 | K22: 27.48 | L22: 27.47 | M22: 27.71 | N22: 27.7 | O22: 27.71 | P22: 23.39 | Q22: 23.54 | R22: 23.47 | S22: 27.05 | T22: 25.09 | U22: 25.05 | V22: 22.54 | W22: 28.26 | X22: 30.115858 | Y22: =10^((#REF!-C$2)/D$2) -> #REF! | Z22: =10^((#REF!-C$3)/D$3) -> #REF! | AA22: =10^((#REF!-C$5)/D$5) -> #REF! | AB22: =10^((#REF!-C$6)/D$6) -> #REF! | AC22: =10^((#REF!-C$4)/D$4) -> #REF! | AD22: =10^((S22-C$7)/D$7) -> 1.5064638 | AE22: =10^((T22-D$8)/E$8) -> 1.6395255 | AF22: =10^((U22-C$9)/D$9) -> 3.2576867 | AG22: =10^((V22-C$10)/D$10) -> 59.669276 | AH22: =10^((W22-C$11)/D$11) -> 0.14413008 | AI22: =($G$2*Y22/G$4)/($E$2*G$3) -> #REF! | AJ22: =($G$2*Z22/$G$4)/($E$3*G$3) -> #REF! | AK22: =($G$2*AA22/$G$4)/($E$5*G$3) -> #REF! | AL22: =($G$2*AB22/$G$4)/($E$6*G$3) -> #REF! | AM22: =($G$2*AC22/$G$4)/($E$4*G$3) -> #REF! | AN22: =($G$2*AD22/$G$4)/($E$7*G$3) -> 1.2727168e+10 | AO22: =($G$2*AE22/$G$4)/($E$8*G$3) -> 1.13329e+10 | AP22: =($G$2*AF22/$G$4)/($E$9*G$3) -> 2.6778309e+10 | AQ22: =($G$2*AG22/$G$4)/($E$10*G$3) -> 4.4625979e+11 | AR22: =($G$2*AH22/$G$4)/($E$11*G$3) -> 1.3698727e+09
A23: Cold | B23: Macho | C23: Head | D23: 20.58 | E23: 20.57 | F23: 20.57 | G23: 20.3 | H23: 20.37 | I23: 20.33 | J23: 19.56 | K23: 19.52 | L23: 19.54 | M23: 22.24 | N23: 22.24 | O23: 22.24 | P23: 18.19 | Q23: 18.26 | R23: 18.22 | S23: 20.38 | T23: 21.6 | U23: 21.03 | V23: 23.65 | W23: 22.84 | X23: 26.291117 | Y23: =10^((#REF!-C$2)/D$2) -> #REF! | Z23: =10^((#REF!-C$3)/D$3) -> #REF! | AA23: =10^((#REF!-C$5)/D$5) -> #REF! | AB23: =10^((#REF!-C$6)/D$6) -> #REF! | AC23: =10^((#REF!-C$4)/D$4) -> #REF! | AD23: =10^((S23-C$7)/D$7) -> 131.06176 | AE23: =10^((T23-D$8)/E$8) -> 1.5426904 | AF23: =10^((U23-C$9)/D$9) -> 60.069275 | AG23: =10^((V23-C$10)/D$10) -> 29.121621 | AH23: =10^((W23-C$11)/D$11) -> 6.7535395 | AI23: =($G$2*Y23/G$4)/($E$2*G$3) -> #REF! | AJ23: =($G$2*Z23/$G$4)/($E$3*G$3) -> #REF! | AK23: =($G$2*AA23/$G$4)/($E$5*G$3) -> #REF! | AL23: =($G$2*AB23/$G$4)/($E$6*G$3) -> #REF! | AM23: =($G$2*AC23/$G$4)/($E$4*G$3) -> #REF! | AN23: =($G$2*AD23/$G$4)/($E$7*G$3) -> 1.1072586e+12 | AO23: =($G$2*AE23/$G$4)/($E$8*G$3) -> 1.0663547e+10 | AP23: =($G$2*AF23/$G$4)/($E$9*G$3) -> 4.9377174e+11 | AQ23: =($G$2*AG23/$G$4)/($E$10*G$3) -> 2.1779732e+11 | AR23: =($G$2*AH23/$G$4)/($E$11*G$3) -> 6.418847e+10
A24: Cold | B24: Macho | C24: Thorax | D24: 14.94 | E24: 15.31 | F24: 15.12 | G24: 14.79 | H24: 14.85 | I24: 14.82 | J24: 16.14 | K24: 16.51 | L24: 16.33 | M24: 20.19 | N24: 20.26 | O24: 20.23 | P24: 18.01 | Q24: 18.13 | R24: 18.07 | S24: 19.98 | T24: 20.36 | U24: 19.57 | V24: 20.72 | W24: 18.9 | X24: 22.396412 | Y24: =10^((#REF!-C$2)/D$2) -> #REF! | Z24: =10^((#REF!-C$3)/D$3) -> #REF! | AA24: =10^((#REF!-C$5)/D$5) -> #REF! | AB24: =10^((#REF!-C$6)/D$6) -> #REF! | AC24: =10^((#REF!-C$4)/D$4) -> #REF! | AD24: =10^((S24-C$7)/D$7) -> 171.31244 | AE24: =10^((T24-D$8)/E$8) -> 1.5096798 | AF24: =10^((U24-C$9)/D$9) -> 173.12115 | AG24: =10^((V24-C$10)/D$10) -> 193.44445 | AH24: =10^((W24-C$11)/D$11) -> 110.68312 | AI24: =($G$2*Y24/G$4)/($E$2*G$3) -> #REF! | AJ24: =($G$2*Z24/$G$4)/($E$3*G$3) -> #REF! | AK24: =($G$2*AA24/$G$4)/($E$5*G$3) -> #REF! | AL24: =($G$2*AB24/$G$4)/($E$6*G$3) -> #REF! | AM24: =($G$2*AC24/$G$4)/($E$4*G$3) -> #REF! | AN24: =($G$2*AD24/$G$4)/($E$7*G$3) -> 1.4473113e+12 | AO24: =($G$2*AE24/$G$4)/($E$8*G$3) -> 1.0435367e+10 | AP24: =($G$2*AF24/$G$4)/($E$9*G$3) -> 1.4230625e+12 | AQ24: =($G$2*AG24/$G$4)/($E$10*G$3) -> 1.4467492e+12 | AR24: =($G$2*AH24/$G$4)/($E$11*G$3) -> 1.0519787e+12
A25: Cold | B25: Macho | C25: Abdomen | D25: 20.82 | E25: 21.33 | F25: 21.07 | G25: 21.49 | H25: 21.57 | I25: 21.53 | J25: 22.96 | K25: 22.72 | L25: 22.84 | M25: 26.37 | N25: 26.17 | O25: 26.27 | P25: 20.35 | Q25: 20.35 | R25: 20.35 | S25: 24.52 | T25: 24.21 | U25: 23.66 | V25: 26.77 | W25: 25.68 | X25: 22.532652 | Y25: =10^((#REF!-C$2)/D$2) -> #REF! | Z25: =10^((#REF!-C$3)/D$3) -> #REF! | AA25: =10^((#REF!-C$5)/D$5) -> #REF! | AB25: =10^((#REF!-C$6)/D$6) -> #REF! | AC25: =10^((#REF!-C$4)/D$4) -> #REF! | AD25: =10^((S25-C$7)/D$7) -> 8.1966744 | AE25: =10^((T25-D$8)/E$8) -> 1.6145501 | AF25: =10^((U25-C$9)/D$9) -> 8.9241477 | AG25: =10^((V25-C$10)/D$10) -> 3.8774747 | AH25: =10^((W25-C$11)/D$11) -> 0.89964061 | AI25: =($G$2*Y25/G$4)/($E$2*G$3) -> #REF! | AJ25: =($G$2*Z25/$G$4)/($E$3*G$3) -> #REF! | AK25: =($G$2*AA25/$G$4)/($E$5*G$3) -> #REF! | AL25: =($G$2*AB25/$G$4)/($E$6*G$3) -> #REF! | AM25: =($G$2*AC25/$G$4)/($E$4*G$3) -> #REF! | AN25: =($G$2*AD25/$G$4)/($E$7*G$3) -> 6.924856e+10 | AO25: =($G$2*AE25/$G$4)/($E$8*G$3) -> 1.1160262e+10 | AP25: =($G$2*AF25/$G$4)/($E$9*G$3) -> 7.3356835e+10 | AQ25: =($G$2*AG25/$G$4)/($E$10*G$3) -> 2.8999196e+10 | AR25: =($G$2*AH25/$G$4)/($E$11*G$3) -> 8.5505615e+09
A26: Cold | B26: Macho | C26: Head | D26: 20.21 | E26: 19.85 | F26: 20.03 | G26: 21.21 | H26: 21.3 | I26: 21.25 | J26: 20 | K26: 20.05 | L26: 20.02 | M26: 23.01 | N26: 23.66 | O26: 23.34 | P26: 19.76 | Q26: 19.93 | R26: 19.85 | S26: 22.14 | T26: 21.42 | U26: 21.86 | V26: 26.1 | W26: 24.44 | X26: 30.000534 | Y26: =10^((#REF!-C$2)/D$2) -> #REF! | Z26: =10^((#REF!-C$3)/D$3) -> #REF! | AA26: =10^((#REF!-C$5)/D$5) -> #REF! | AB26: =10^((#REF!-C$6)/D$6) -> #REF! | AC26: =10^((#REF!-C$4)/D$4) -> #REF! | AD26: =10^((S26-C$7)/D$7) -> 40.336604 | AE26: =10^((T26-D$8)/E$8) -> 1.5378542 | AF26: =10^((U26-C$9)/D$9) -> 32.909204 | AG26: =10^((V26-C$10)/D$10) -> 5.9785072 | AH26: =10^((W26-C$11)/D$11) -> 2.1692679 | AI26: =($G$2*Y26/G$4)/($E$2*G$3) -> #REF! | AJ26: =($G$2*Z26/$G$4)/($E$3*G$3) -> #REF! | AK26: =($G$2*AA26/$G$4)/($E$5*G$3) -> #REF! | AL26: =($G$2*AB26/$G$4)/($E$6*G$3) -> #REF! | AM26: =($G$2*AC26/$G$4)/($E$4*G$3) -> #REF! | AN26: =($G$2*AD26/$G$4)/($E$7*G$3) -> 3.4077866e+11 | AO26: =($G$2*AE26/$G$4)/($E$8*G$3) -> 1.0630117e+10 | AP26: =($G$2*AF26/$G$4)/($E$9*G$3) -> 2.7051492e+11 | AQ26: =($G$2*AG26/$G$4)/($E$10*G$3) -> 4.4712581e+10 | AR26: =($G$2*AH26/$G$4)/($E$11*G$3) -> 2.0617632e+10
... A67: Heat | B67: Macho | C67: Abdomen | D67: 20.11 | E67: 20.37 | F67: 20.24 | G67: 21.01 | H67: 20.64 | I67: 20.82 | J67: 22.22 | K67: 22.24 | L67: 22.23 | M67: 26.37 | N67: 26.57 | O67: 26.47 | P67: 21.73 | Q67: 22.27 | R67: 22 | S67: 26.71 | T67: 24.01 | U67: 24.18 | V67: 23.17 | W67: 25.59 | X67: 18.98381 | Y67: =10^((#REF!-C$2)/D$2) -> #REF! | Z67: =10^((#REF!-C$3)/D$3) -> #REF! | AA67: =10^((#REF!-C$5)/D$5) -> #REF! | AB67: =10^((#REF!-C$6)/D$6) -> #REF! | AC67: =10^((#REF!-C$4)/D$4) -> #REF! | AD67: =10^((S67-C$7)/D$7) -> 1.8915798 | AE67: =10^((T67-D$8)/E$8) -> 1.6089271 | AF67: =10^((U67-C$9)/D$9) -> 6.1212313 | AG67: =10^((V67-C$10)/D$10) -> 39.713072 | AH67: =10^((W67-C$11)/D$11) -> 0.95898668 | AI67: =($G$2*Y67/G$4)/($E$2*G$3) -> #REF! | AJ67: =($G$2*Z67/$G$4)/($E$3*G$3) -> #REF! | AK67: =($G$2*AA67/$G$4)/($E$5*G$3) -> #REF! | AL67: =($G$2*AB67/$G$4)/($E$6*G$3) -> #REF! | AM67: =($G$2*AC67/$G$4)/($E$4*G$3) -> #REF! | AN67: =($G$2*AD67/$G$4)/($E$7*G$3) -> 1.5980771e+10 | AO67: =($G$2*AE67/$G$4)/($E$8*G$3) -> 1.1121395e+10 | AP67: =($G$2*AF67/$G$4)/($E$9*G$3) -> 5.0316755e+10 | AQ67: =($G$2*AG67/$G$4)/($E$10*G$3) -> 2.9700959e+11 | AR67: =($G$2*AH67/$G$4)/($E$11*G$3) -> 9.1146114e+09
C68: SD | P68: =_xlfn.STDEV.S(#REF!) -> #REF! | Q68: =_xlfn.STDEV.S(#REF!) -> #REF! | R68: =_xlfn.STDEV.S(#REF!) -> #REF! | S68: =_xlfn.STDEV.S(S14:S67) -> 4.1563997 | T68: =_xlfn.STDEV.S(T14:T67) -> 2.9202251 | U68: =_xlfn.STDEV.S(U14:U67) -> 3.3324226 | V68: =_xlfn.STDEV.S(V14:V67) -> 4.8678119 | W68: =_xlfn.STDEV.S(W14:W67) -> 4.0946512

Sheet RefFinder
A1: Genes | B1: Condition | C1: ranking
A2: ACT1 | B2: Sex | C2: 1.78
A3: ACT2 | B3: Sex | C3: 1.86
A4: UQCC | B4: Sex | C4: 4.05
A5: AK | B5: Sex | C5: 4.28
A6: RPL3 | B6: Sex | C6: 4.76
A7: pAbp | B7: Sex | C7: 4.82
A8: ANX | B8: Sex | C8: 5.12
A9: eEfa1 | B9: Sex | C9: 6.16
A10: GAPDH | B10: Sex | C10: 7.35
A11: eEfa1 | B11: Tissue | C11: 1.97
A12: pAbp | B12: Tissue | C12: 2.63
A13: ACT1 | B13: Tissue | C13: 3.6
... A28: GAPDH | B28: Treatment | C28: 8.45

Sheet Expression stability
A2: Genorm | J2: NormFinder | M2: RefFinder | R2: RefFinder | V2: Genorm | Y2: NormFinder
A3: Sex
A4: Variation | D4: Gene | E4: M | J4: Gene | K4: S | M4: Gene | N4: Geomean of ranking values | R4: Genes | S4: Geomean of ranking values | V4: Gene name | W4: Stability value | Y4: Gene name | Z4: Stability value
A5: 2 | B5: 0.1261719 | D5: Actin1 | E5: 0.3920587 | J5: Actin1 | K5: 0.538 | M5: Actin1 | N5: 1.57 | R5: Actin1 | S5: 1.78
A6: 3 | B6: 0.1299858 | D6: Actin2 | E6: 0.3920587 | J6: Ubiquinol | K6: 0.551 | M6: Actin2 | N6: 2.55 | R6: Actin2 | S6: 1.86 | V6: Actin1 | Actin2 | W6: 0.392 | Y6: ACT1 | Z6: 0.37
A7: 4 | B7: 0.1255404 | D7: pABp | E7: 0.4147594 | J7: Actin2 | K7: 0.705 | M7: Ubiquinol | N7: 3.46 | R7: Ubiquinol | S7: 4.05 | V7: pAbp | W7: 0.415 | Y7: ACT2 | Z7: 0.529
A8: 5 | B8: 0.1373138 | D8: Arginine | E8: 0.4852062 | J8: Arginine | K8: 0.835 | M8: Arginine | N8: 4.76 | R8: Arginine | S8: 4.28 | V8: Arginine | W8: 0.485 | Y8: UCCR | Z8: 0.554
A9: 6 | B9: 0.1908894 | D9: Eefa1 | E9: 0.5689881 | J9: Annexin | K9: 0.847 | M9: RSP3A | N9: 5.2 | R9: RPL3 | S9: 4.76 | V9: eEf1α | W9: 0.569 | Y9: AK | Z9: 0.691
A10: 7 | B10: 0.1728983 | D10: Ubiquinol | E10: 0.6756394 | J10: pAbp | K10: 0.95 | M10: Annexin | N10: 5.21 | R10: pAbp | S10: 4.82 | V10: UCCR | W10: 0.676 | Y10: pAbp | Z10: 0.781
A11: 8 | B11: 0.2 | D11: Annexine | E11: 0.8846489 | J11: Eefa1 | K11: 0.975 | M11: pAbp | N11: 5.48 | R11: Annexin | S11: 5.12 | V11: Annexin | W11: 0.885 | Y11: eEf1α | Z11: 0.847
D12: RPL3 | E12: 1.0237047 | J12: RPL3 | K12: 1.069 | M12: RPL3 | N12: 5.66 | R12: Eefa1 | S12: 6.16 | V12: RPL3 | W12: 1.024 | Y12: ANX | Z12: 1.008
D13: RPS3A | E13: 1.1807878 | J13: RSP3A | K13: 1.504 | M13: Eefa1 | N13: 6.59 | R13: GAPDH | S13: 7.35 | V13: GAPDH | W13: 1.23 | Y13: RPL3 | Z13: 1.246
D14: GAPDH | E14: 1.3250503 | J14: GAPDH | K14: 1.678 | M14: GAPDH | N14: 8.41 | Y14: GAPDH | Z14: 1.794
A19: Tissues
A20: Genorm | J20: NormFinder | M20: RefFinder | Q20: RefFinder | U20: Genorm | X20: NormFinder
A21: Variation | D21: Gene | E21: M | I21: Gene | J21: S | M21: Gene | N21: Geomean of ranking values | Q21: Genes | R21: Geomean of ranking values | U21: Gene name | V21: Stability value | X21: Gene name | Y21: Stability value
A22: 2 | B22: 0.35604 | D22: Actin2 | E22: 0.6284247 | I22: Eefa1 | J22: 1.159 | M22: Eefa1 | N22: 2.11 | Q22: Eefa1 | R22: 1.97
A23: 3 | B23: 0.2890652 | D23: Arginine | E23: 0.6284247 | I23: Annexin | J23: 1.362 | M23: pAbp | N23: 3.03 | Q23: pAbp | R23: 2.63 | U23: Actin2 | Arginine | V23: 0.628 | X23: eEf1α | Y23: 1.089
A24: 4 | B24: 0.329566 | D24: Actin1 | E24: 0.9471353 | I24: pAbp | J24: 1.399 | M24: Annexin | N24: 4.09 | Q24: Actin1 | R24: 3.6 | U24: ACT1 | V24: 0.947 | X24: pAbp | Y24: 1.236
A25: 5 | B25: 0.3148102 | D25: pAbp | E25: 1.1164859 | I25: Ubiquinol | J25: 1.405 | M25: Actin2 | N25: 4.24 | Q25: Actin2 | R25: 3.72 | U25: pAbp | V25: 1.116 | X25: Ubiquinol | Y25: 1.311
A26: 6 | B26: 0.3130935 | D26: Eefa1 | E26: 1.3752626 | I26: Actin1 | J26: 1.501 | M26: Actin1 | N26: 4.36 | Q26: Arginine | R26: 4.21 | U26: eEf1α | V26: 1.375 | X26: Actin1 | Y26: 1.323
A27: 7 | B27: 0.3839724 | D27: Ubiquinol | E27: 1.6138092 | I27: Actin2 | J27: 1.933 | M27: Arginine | N27: 4.7 | Q27: Ubiquinol | R27: 4.82 | U27: UCCR | V27: 1.614 | X27: Annexin | Y27: 1.581
A28: 8 | B28: 0.3939504 | D28: Annexine | E28: 1.8491132 | I28: Arginine | J28: 1.961 | M28: RPS3A | N28: 4.76 | Q28: Annexin | R28: 5.6 | U28: ANX | V28: 1.849 | X28: Actin2 | Y28: 1.729
D29: RSP3A | E29: 2.1295217 | I29: RPS3A | J29: 2.188 | M29: Ubiquinol | N29: 5.18 | Q29: RPL3 | R29: 5.66 | U29: RPL3 | V29: 2.203 | X29: Arginine | Y29: 1.785
D30: RPL3 | E30: 2.3559805 | I30: RPL3 | J30: 2.561 | M30: RPL3 | N30: 6.84 | Q30: GAPDH | R30: 6.84 | U30: GAPDH | V30: 2.565 | X30: RPL3 | Y30: 2.722
D31: GAPDH | E31: 2.624477 | I31: GAPDH | J31: 3.311 | M31: GAPDH | N31: 7.95 | X31: GAPDH | Y31: 3.496
A33: Temperature
A34: Genorm | I34: NormFinder | M34: RefFinder | Q34: RefFinder | U34: Genorm | X34: NormFinder
A35: Variation | D35: Gene | E35: M | I35: Gene | J35: S | M35: Gene | N35: Geomean of ranking values | Q35: Genes | R35: Geomean of ranking values | U35: Gene name | V35: Stability value | X35: Gene name | Y35: Stability value
A36: 2 | B36: 0.4999697 | D36: Actin2 | E36: 1.045905 | I36: Ubiquinol | J36: 1.075 | M36: Ubiquinol | N36: 2.11 | Q36: Ubiquinol | R36: 1.97
A37: 3 | B37: 0.4168583 | D37: Arginine | E37: 1.045905 | I37: Eefa1 | J37: 1.403 | M37: Arginine | N37: 2.99 | Q37: Arginine | R37: 2.71 | U37: Actin2 | Arginine | V37: 1.046 | X37: UCCR | Y37: 1.055
A38: 4 | B38: 0.3229801 | D38: pAbp | E38: 1.398263 | I38: pAbp | J38: 1.434 | M38: Eefa1 | N38: 3.13 | Q38: pAbp | R38: 3.08 | U38: pAbp | V38: 1.398 | X38: pAbp | Y38: 1.344
A39: 5 | B39: 0.2950476 | D39: Eefa1 | E39: 1.6142178 | I39: Arginine | J39: 1.499 | M39: pAbp | N39: 3.57 | Q39: Eefa1 | R39: 3.36 | U39: eEf1α | V39: 1.614 | X39: AK | Y39: 1.345
A40: 6 | B40: 0.3251317 | D40: Ubiquinol | E40: 1.729775 | I40: Actin2 | J40: 1.712 | M40: Actin2 | N40: 3.87 | Q40: Actin2 | R40: 3.76 | U40: UCCR | V40: 1.73 | X40: eEf1α | Y40: 1.375
A41: 7 | B41: 0.3154415 | D41: Actin1 | E41: 1.84594 | I41: RPL3 | J41: 1.734 | M41: RPS3A | N41: 4.76 | Q41: RPL3 | R41: 4.3 | U41: ACT1 | V41: 1.846 | X41: ACT2 | Y41: 1.572
A42: 8 | B42: 0.3787125 | D42: RPL3 | E42: 2.045914 | I42: Actin1 | J42: 1.758 | M42: RPL3 | N42: 4.92 | Q42: Actin1 | R42: 6 | U42: RPL3 | V42: 2.046 | X42: ACT1 | Y42: 1.681
D43: RPS3A | E43: 2.211939 | I43: RPS3A | J43: 2.082 | M43: Actin1 | N43: 6.48 | Q43: Annexin | R43: 6.73 | U43: ANX | V43: 2.25 | X43: RPL3 | Y43: 1.908
D44: Annexine | E44: 2.345955 | I44: Annexin | J44: 2.336 | M44: Annexin | N44: 7.77 | Q44: GAPDH | R44: 8.45 | U44: GAPDH | V44: 2.579 | X44: ANX | Y44: 2.445
D45: GAPDH | E45: 2.61881 | I45: GAPDH | J45: 3.302 | M45: GAPDH | N45: 9.46 | X45: GAPDH | Y45: 3.359
A49: Cold/ Head/Female | R49: Cold/ Head/Female | AH49: Cold/ Head/Male
...

Sheet Pair_variation
A1: Pairwise | B1: Conditions | C1: Variation
A2: V2/3 | B2: Sex | C2: 0.1261719
A3: V3/4 | B3: Sex | C3: 0.1299858
A4: V4/5 | B4: Sex | C4: 0.1255404
A5: V5/6 | B5: Sex | C5: 0.1373138
A6: V6/7 | B6: Sex | C6: 0.1908894
A7: V7/8 | B7: Sex | C7: 0.1728983
A8: V8/9 | B8: Sex | C8: 0.2
A9: V2/3 | B9: Tissues | C9: 0.35604
A10: V3/4 | B10: Tissues | C10: 0.2890652
A11: V4/5 | B11: Tissues | C11: 0.329566
A12: V5/6 | B12: Tissues | C12: 0.3148102
A13: V6/7 | B13: Tissues | C13: 0.3130935
... A22: V8/9 | B22: Temperature | C22: 0.3787125

Sheet Absolute expression
A1: Gene | B1: Treatment | C1: Sex | D1: Tissue | E1: NC
A2: Actin | B2: Cold (4°C) | C2: Female | D2: H | E2: 2.630102e+10
A3: Actin | B3: Cold (4°C) | C3: Female | D3: T | E3: 9.4545462e+10
A4: Actin | B4: Cold (4°C) | C4: Female | D4: A | E4: 4.2922234e+08
A5: Actin | B5: Cold (4°C) | C5: Female | D5: H | E5: 2.7236713e+10
A6: Actin | B6: Cold (4°C) | C6: Female | D6: T | E6: 4.0474292e+11
A7: Actin | B7: Cold (4°C) | C7: Female | D7: A | E7: 6.1797703e+08
A8: Actin | B8: Cold (4°C) | C8: Female | D8: H | E8: 4.8042374e+09
A9: Actin | B9: Cold (4°C) | C9: Female | D9: T | E9: 4.6872821e+11
A10: Actin | B10: Cold (4°C) | C10: Female | D10: A | E10: 7.1880203e+08
A11: Actin | B11: Cold (4°C) | C11: Male | D11: H | E11: 1.5947502e+10
A12: Actin | B12: Cold (4°C) | C12: Male | D12: T | E12: 6.618589e+11
A13: Actin | B13: Cold (4°C) | C13: Male | D13: A | E13: 1.1326951e+10
... A540: Actin | B540: Control (25°C) | C540: Male | D540: A | E540: 8.6160207e+11

Sheet Absolute expression tissues
A1: Gene | B1: Treatment | C1: Sex | D1: Tagma | E1: NC
A2: Actin | B2: Control (25°C) | C2: Female | D2: H | E2: 5.6166833e+09
A3: Actin | B3: Control (25°C) | C3: Female | D3: H | E3: 5.9937349e+10
A4: Actin | B4: Control (25°C) | C4: Female | D4: H | E4: 3.3751415e+09
A5: Actin | B5: Control (25°C) | C5: Male | D5: H | E5: 83029017
A6: Actin | B6: Control (25°C) | C6: Male | D6: H | E6: 1.5517777e+09
A7: Actin | B7: Control (25°C) | C7: Male | D7: H | E7: 2.6873839e+08
A8: Actin | B8: Control (25°C) | C8: Female | D8: T | E8: 3.8706143e+11
A9: Actin | B9: Control (25°C) | C9: Female | D9: T | E9: 7.0744926e+11
A10: Actin | B10: Control (25°C) | C10: Female | D10: T | E10: 4.9286184e+11
A11: Actin | B11: Control (25°C) | C11: Male | D11: T | E11: 2.0247737e+11
A12: Actin | B12: Control (25°C) | C12: Male | D12: T | E12: 2.25514e+11
A13: Actin | B13: Control (25°C) | C13: Male | D13: T | E13: 6.6426222e+10
... A181: Ubiquinol | B181: Control (25°C) | C181: Male | D181: A | E181: 3.7108997e+08

Sheet Absolute expression sex
A1: Gene | B1: Treatment | C1: Sex | D1: NC
A2: Actin | B2: Control (25°C) | C2: Female | D2: 1.2794277e+10
A3: Actin | B3: Control (25°C) | C3: Female | D3: 3.9139325e+10
A4: Actin | B4: Control (25°C) | C4: Female | D4: 1.3777254e+10
A5: Actin | B5: Control (25°C) | C5: Male | D5: 8.5571053e+08
A6: Actin | B6: Control (25°C) | C6: Male | D6: 3.4264603e+09
A7: Actin | B7: Control (25°C) | C7: Male | D7: 1.9584179e+09
A8: Actin2 | B8: Control (25°C) | C8: Female | D8: 3.7766126e+10
A9: Actin2 | B9: Control (25°C) | C9: Female | D9: 1.4119261e+11
A10: Actin2 | B10: Control (25°C) | C10: Female | D10: 8.0562573e+10
A11: Actin2 | B11: Control (25°C) | C11: Male | D11: 1.9159811e+09
A12: Actin2 | B12: Control (25°C) | C12: Male | D12: 1.1524243e+10
A13: Actin2 | B13: Control (25°C) | C13: Male | D13: 7.2184501e+09
... A61: Ubiquinol | B61: Control (25°C) | C61: Male | D61: 3.6138556e+09

Sheet Cq_tagged
A1: Gene | B1: Treatment | C1: Sex | D1: Tissue | E1: Ct
A2: ACT1 | B2: Cold | C2: Female | D2: H | E2: 19.841928
A3: ACT1 | B3: Cold | C3: Female | D3: T | E3: 17.969883
A4: ACT1 | B4: Cold | C4: Female | D4: A | E4: 25.863309
A5: ACT1 | B5: Cold | C5: Female | D5: H | E5: 19.79078
A6: ACT1 | B6: Cold | C6: Female | D6: T | E6: 15.842229
A7: ACT1 | B7: Cold | C7: Female | D7: A | E7: 25.33003
A8: ACT1 | B8: Cold | C8: Female | D8: H | E8: 22.329423
A9: ACT1 | B9: Cold | C9: Female | D9: T | E9: 15.627483
A10: ACT1 | B10: Cold | C10: Female | D10: A | E10: 25.108899
A11: ACT1 | B11: Cold | C11: Male | D11: H | E11: 20.573944
A12: ACT1 | B12: Cold | C12: Male | D12: T | E12: 15.122657
A13: ACT1 | B13: Cold | C13: Male | D13: A | E13: 21.074509
... A487: UCCR | B487: Heat | C487: Male | D487: A | E487: 25.59

Sheet P_value
A1: Gene | B1: Conditions | C1: P_value
A2: pAbp | B2: Temperature | C2: 0.489
A3: ANX | B3: Temperature | C3: 0.412
A4: ACT1 | B4: Temperature | C4: 0.399
A5: AK | B5: Temperature | C5: 0.392
A6: ACT2 | B6: Temperature | C6: 0.335
A7: RPL3 | B7: Temperature | C7: 0.327
A8: eEfa1 | B8: Temperature | C8: 0.159
A9: UCCR | B9: Temperature | C9: 0.0808
A10: GAPDH | B10: Temperature | C10: 0.00884
A11: UCCR | B11: Sex | C11: 0.945
A12: GAPDH | B12: Sex | C12: 0.82
A13: ACT2 | B13: Sex | C13: 0.752
... A64: GAPDH | B64: Temp+Sex+Tissue | C64: 0.381

Sheet EGR
A1: Gene | B1: Quality | C1: Treatment | D1: Sex | E1: Tissue | F1: EGR | G1: Log_EGR
A2: HSP90 | B2: best | C2: Control | D2: Male | E2: H | F2: 1.2061496 | G2: 0.081401176
A3: HSP90 | B3: best | C3: Control | D3: Male | E3: H | F3: 0.088174045 | G3: -1.0546592
A4: HSP90 | B4: best | C4: Control | D4: Male | E4: H | F4: 9.4028186 | G4: 0.97325806
A5: HSP90 | B5: best | C5: Control | D5: Male | E5: T | F5: 1.3304043 | G5: 0.12398365
A6: HSP90 | B6: best | C6: Control | D6: Male | E6: T | F6: 0.13480905 | G6: -0.87028096
A7: HSP90 | B7: best | C7: Control | D7: Male | E7: T | F7: 5.5756731 | G7: 0.7462973
A8: HSP90 | B8: best | C8: Control | D8: Male | E8: A | F8: 1.1859871 | G8: 0.074079967
A9: HSP90 | B9: best | C9: Control | D9: Male | E9: A | F9: 0.28217181 | G9: -0.54948637
A10: HSP90 | B10: best | C10: Control | D10: Male | E10: A | F10: 2.9881776 | G10: 0.4754064
A11: HSP90 | B11: best | C11: Cold | D11: Male | E11: H | F11: 83.786907 | G11: 1.9231762
A12: HSP90 | B12: best | C12: Cold | D12: Male | E12: H | F12: 75.836382 | G12: 1.8798776
A13: HSP90 | B13: best | C13: Cold | D13: Male | E13: H | F13: 1.2437999 | G13: 0.094750501
... A109: HSP90 | B109: worst | C109: Heat | D109: Female | E109: A | F109: 0.21686414 | G109: -0.66381225
